Workbook
Name mgr: '[1]Employee Information'!$A$2:$P$65

Sheet Currencies
A1: Currency Code | B1: Currency Name | C1: Rounding Method | D1: Exchange Currency Code | E1: Exchange Rate | F1: Exchange Eff Date
A2: USD | B2: US Dollar | E2: 1 | G2: $
A3: CAD | B3: Canadian Dollar | E3: 2 | G3: $
A4: AUD | B4: Australian Dollar | E4: 3 | G4: $
A5: EUR | B5: Euro | E5: 4 | G5: €
A6: BRL | B6: Brazilian Real | E6: 5 | G6: R$
A7: IDR | B7: Indonesian Rupiah | E7: 6 | G7: Rp
A8: AED | B8: U.A.E. Dirham | E8: 7 | G8: د.إ
A9: GBP | B9: British Pound | E9: 8 | G9: £

Sheet Rating Items
A1: Rating Alpha | B1: Rating | C1: Rating Group | D1: Distribution Pct | E1: Rating Name
A2: 1 | B2: 1 | C2: 1 | D2: 0
A3: 2 | B3: 2 | C3: 2 | D3: 0.1
A4: 3 | B4: 3 | C4: 3 | D4: 0.55
A5: 4 | B5: 4 | C5: 4 | D5: 0.25
A6: 5 | B6: 5 | C6: 5 | D6: 0.1

Sheet Guideline Divisions
A1: Guideline Name | B1: Rating Name | C1: Guideline Div Name | D1: Guideline Div Seq | E1: Guideline Div Val
C2: Q1 | D2: 1 | E2: 80
C3: Q2 | D3: 2 | E3: 100
C4: Q3 | D4: 3 | E4: 115
C5: Q4 | D5: 4 | E5: 135
A6: First | C6: Q1 | D6: 1 | E6: 80
A7: First | C7: Q2 | D7: 2 | E7: 100
A8: First | C8: Q3 | D8: 3 | E8: 115
A9: First | C9: Q4 | D9: 4 | E9: 135
A10: Second | C10: Q1 | D10: 1 | E10: 80
A11: Second | C11: Q2 | D11: 2 | E11: 100
A12: Second | C12: Q3 | D12: 3 | E12: 115
A13: Second | C13: Q4 | D13: 4 | E13: 135
A14: Third | C14: Q1 | D14: 1 | E14: 80
A15: Third | C15: Q2 | D15: 2 | E15: 100
A16: Third | C16: Q3 | D16: 3 | E16: 115
A17: Third | C17: Q4 | D17: 4 | E17: 135
... A21: Forth | C21: Q4 | D21: 4 | E21: 100

Sheet Budget Pools
A1: Budget Pool Name | B1: Pct Based? | C1: Budget Pool Pct | D1: Holdback Pct | E1: Currency Code | F1: Budget Pool Amount | G1: Holdback Pool Amount | H1: Spend Range Adj? | I1: Spend Merit? | J1: Spend Lump Sum? | K1: Spend Internal Equity? | L1: Spend Promo? | M1: Spend Market Adj? | N1: Spend Other? | O1: Spend Variable 1? | P1: Spend Variable 2? | Q1: Tgt Plan?
A2: June Budget | B2: y | C2: 40 | D2: 20 | G2: 4000 | H2: yes | I2: y | J2: 0 | K2: 0 | L2: 1 | M2: 1 | N2: 0 | O2: y | P2: n | Q2: yes
A3: july Budget | B3: n | C3: 30 | D3: 10 | E3: USD | F3: 6000 | G3: 2000 | H3: yes | I3: y | J3: 0 | K3: 0 | L3: 1 | M3: 1 | N3: 0 | O3: y | P3: n | Q3: yes
A4: Auguest Budget | C4: 40 | D4: 30 | E4: USD | F4: 7000 | G4: 3000 | H4: yes | I4: y | J4: 0 | K4: 0 | L4: 1 | M4: 1 | N4: 0 | O4: y | P4: n | Q4: yes
A5: September Budget | C5: 50 | D5: 40 | E5: CAD | F5: 20000 | G5: 1000 | H5: yes | I5: y | J5: 0 | K5: 0 | L5: 1 | M5: 1 | N5: 0 | O5: y | P5: n | Q5: yes
A6: oct Budget | B6: 0 | C6: 20 | D6: 50 | E6: USD | F6: 40000 | G6: 100 | H6: yes | I6: y | J6: 0 | K6: 0 | L6: 1 | M6: 1 | N6: 0 | O6: y | P6: n | Q6: yes
A7: November Budget | B7: 1 | C7: 20 | D7: 15 | F7: 50000 | G7: 200 | H7: yes | I7: y | J7: 0 | K7: 0 | L7: 1 | M7: 1 | N7: 0 | O7: y | P7: n | Q7: yes

Sheet Budget Pool Divisions
A1: Budget Pool Name | B1: Pool Div Name | C1: Pool Div Pct | D1: Pool Div Merit | E1: Pool Div Merit Ls | F1: Pool Div Internal Equity | G1: Pool Div Promo | H1: Pool Div Market Adj | I1: Pool Div Other | J1: Pool Div Is Variable 1 | K1: Pool Div Is Variable 2
A2: June Budget | B2: A | C2: 1
A3: july Budget | B3: B
A4: Auguest Budget | B4: C | C4: 1
A5: September Budget | B5: D
A6: oct Budget | B6: E | C6: 2
A7: November Budget | B7: F

Sheet Salary Structure Items
A1: Structure Name | B1: Structure Region | C1: Salary Grade | D1: Salary Gradexx | E1: Structure Item | F1: Structure Min Amt | G1: Structure Mid Amt | H1: Structure Max Amt | I1: Currency Code | J1: Budget Pool Name | K1: Structure seq
A2: Exempt US | C2: E06 | D2: E06 | E2: E06 | F2: 12400 | G2: 15200 | H2: 19100 | I2: USD | K2: 1
A3: Exempt US | C3: E08 | D3: E08 | E3: E08 | F3: 15400 | G3: 19200 | H3: 23100 | I3: USD | K3: 2
A4: Exempt US | C4: E10 | D4: E10 | E4: E10 | F4: 16000 | G4: 20000 | H4: 30000 | I4: USD | K4: 3
A5: Exempt US | C5: E12 | D5: E12 | E5: E12 | F5: 23700 | G5: 31500 | H5: 39400 | I5: USD | K5: 4
A6: Exempt US | C6: E14 | D6: E14 | E6: E14 | F6: 29400 | G6: 42000 | H6: 54600 | I6: USD | K6: 5
A7: Exempt US | C7: E16 | D7: E16 | E7: E16 | F7: 36200 | G7: 51600 | H7: 67100 | I7: USD | K7: 6
A8: Exempt US | C8: E18 | D8: E18 | E8: E18 | F8: 42700 | G8: 61000 | H8: 79300 | I8: USD | K8: 7
A9: Exempt US | C9: E20 | D9: E20 | E9: E20 | F9: 48100 | G9: 74000 | H9: 99900 | I9: USD | K9: 8
A10: Exempt US | C10: E22 | D10: E22 | E10: E22 | F10: 53300 | G10: 82000 | H10: 110700 | I10: USD | K10: 9
A11: Exempt US | C11: E24 | D11: E24 | E11: E24 | F11: 57000 | G11: 95000 | H11: 133000 | I11: USD | K11: 10
A12: Exempt US | C12: E26 | D12: E26 | E12: E26 | F12: 63000 | G12: 105000 | H12: 147000 | I12: USD | K12: 11
A13: Exempt US | C13: E28 | D13: E28 | E13: E28 | F13: 74400 | G13: 124000 | H13: 173600 | I13: USD | K13: 12
... A32: Exempt CAD | C32: E29 | D32: E29 | E32: E29 | F32: 115600 | G32: 196000 | H32: 270400 | I32: CAD | K32: 31
A33: Exempt CAD | C33: E30 | D33: E30 | E33: E30 | F33: 121500 | G33: 202500 | H33: 283500 | K33: 32
A34: Exempt CAD | C34: E32 | D34: E32 | E34: E32 | F34: 141300 | G34: 235500 | H34: 329700 | I34: CAD | K34: 33
A35: Exempt CAD | C35: E34 | D35: E34 | E35: E34 | F35: 169200 | G35: 282000 | H35: 394800 | I35: CAD | K35: 34
A36: Exempt CAD | C36: E36 | D36: E36 | E36: E36 | F36: 199800 | G36: 333000 | H36: 466200 | I36: CAD | K36: 35
A37: Exempt CAD | C37: E38 | D37: E38 | E37: E38 | F37: 239400 | G37: 399000 | H37: 558600 | I37: CAD | K37: 36
A38: Exempt CAD | C38: E40 | D38: E40 | E38: E40 | F38: 288000 | G38: 480000 | H38: 672000 | I38: CAD | K38: 37
B39: Europe | C39: E20 | D39: E20 | E39: E20 | F39: 56000 | G39: 66000 | H39: 76000 | I39: EUR | K39: 38 | O39: Exempt EUR
B40: Australian | C40: E20 | D40: E20 | E40: E20 | F40: 57000 | G40: 67000 | H40: 77000 | I40: AUD | K40: 39 | O40: Exempt AUD
B41: Brazil | C41: E20 | D41: E20 | E41: E20 | F41: 58000 | G41: 68000 | H41: 78000 | I41: BRL | K41: 40 | O41: Exempt BRL
B42: Indonesia | C42: E20 | D42: E20 | E42: E20 | F42: 59000 | G42: 69000 | H42: 79000 | I42: IDR | K42: 41 | O42: Exempt IDR
B43: UAE | C43: E20 | D43: E20 | E43: E20 | F43: 60000 | G43: 70000 | H43: 80000 | I43: AED | K43: 42 | O43: Exempt AED
B44: Australian | C44: E21 | D44: E21 | E44: E21 | F44: 61000 | G44: 71000 | H44: 81000 | I44: AED | K44: 43
B45: Brazil | C45: E21 | D45: E21 | E45: E21 | F45: 63000 | G45: 72000 | H45: 82000 | I45: BRL | K45: 44

Sheet Employee Information
A1: Employee Id | B1: Emp Id | C1: Name | D1: Employee Name | E1: Job Title | F1: Job Family Name | G1: In HR? | H1: Rating Name | I1: Language Preference | J1: Per Pay Type | K1: Per Pay Amt | L1: Emp Status | M1: Hire Date | N1: DOH | O1: Mgr Emp Id | P1: Manager ID | Q1: Hair Color | R1: Manager Name | S1: Mgr Name | T1: HR Rep Emp Id | U1: HR Rep Name | V1: HR Area Rep Emp ID | W1: HR Area Rep Name | X1: Job Code | Y1: Job Titlexxx | Z1: Structure Name | AA1: Structure Region | AB1: Salary Grade | AC1: Structure Item | AD1: Currency Code | AE1: Starting Salary Amt | AF1: Current Annual Salary | AG1: Rating Alpha | AH1: Prior Rating Alpha | AI1: Min Amt | AJ1: Mid Amt | AK1: Max Amt | AL1: Position in Range | AM1: Range Penetration Label | AN1: Variable 1 Basis | AO1: Cur Variable 1 Tgt Val | AP1: Variable 2 Basis | AQ1: Cur Variable 2 Tgt Val | AR1: Hours Baseline | AS1: Hours Worked | AT1: Is Meeting Expectations
A2: 2009 | B2: 2009 | C2: Grimm, Briañ | D2: Grimm, Briañ | E2: Certified Doc Aide | F2: Accounting! | G2: TRUE | J2: Annually | L2: Active | M2: 45767 | N2: 45767 | O2: 2001 | P2: 2001 | Q2: Blond | R2: Ward Jr Lloyd | S2: Ward Jr Lloyd | T2: 80 | U2: Jackson, Charmain | V2: 80 | W2: Jackson, Charmain | X2: J001 | Y2: Programmer | Z2: Exempt CAD | AB2: E18 | AC2: E18 | AD2: AUD | AE2: 100000 | AF2: 100000 | AG2: 1 | AH2: Good | AI2: 42700 | AJ2: 61000 | AK2: 79300 | AL2: Q1 | AM2: Q1 | AO2: 5000 | AQ2: 30 | AR2: 40 | AS2: 40 | AT2: Stage meeting
A3: 2004 | B3: 2004 | C3: Janish Betty | D3: Janish Betty | E3: Certified Nurse Aide | F3: Operations@ | G3: TRUE | J3: Annually (1yr) | L3: Active | M3: 45767 | N3: 45767 | O3: 2001 | P3: 2001 | Q3: Brown | R3: Ward Jr Lloyd | S3: Ward Jr Lloyd | T3: 80 | U3: Jackson, Charmain | V3: 80 | W3: Jackson, Charmain | X3: J002 | Y3: Programmer | Z3: Exempt CAD | AB3: E18 | AC3: E18 | AD3: AUD | AE3: 100000 | AF3: 100000 | AG3: 2 | AH3: Good | AI3: 42700 | AJ3: 61000 | AK3: 79300 | AL3: Q2 | AM3: Q2 | AO3: 5000 | AQ3: 30 | AR3: 40 | AS3: 40 | AT3: Stage meeting
A4: 2002 | B4: 2002 | C4: Keeling, Larry | D4: Keeling, Larry | E4: LVN | F4: Operations# | G4: 0 | J4: Monthly (12) | L4: Active | M4: 45767 | N4: 45767 | O4: 2001 | P4: 2001 | Q4: Grey | R4: Ward Jr Lloyd | S4: Ward Jr Lloyd | T4: 80 | U4: Jackson, Charmain | V4: 80 | W4: Jackson, Charmain | X4: J003 | Y4: Programmer | Z4: Exempt CAD | AB4: E18 | AC4: E18 | AD4: AUD | AE4: 100000 | AF4: 100000 | AG4: 2 | AH4: Good | AI4: 42700 | AJ4: 61000 | AK4: 79300 | AL4: Q3 | AM4: Q3 | AO4: 5000 | AQ4: 30 | AR4: 40 | AS4: 40 | AT4: Stage meeting
A5: 2008 | B5: 2008 | C5: Krendick, Jasoñ | D5: Krendick, Jasoñ | E5: RN | F5: Operations$ | J5: Monthly | L5: Active | M5: 45767 | N5: 45767 | O5: 2001 | P5: 2001 | Q5: Red | R5: Ward Jr Lloyd | S5: Ward Jr Lloyd | T5: 80 | U5: Jackson, Charmain | V5: 80 | W5: Jackson, Charmain | X5: J004 | Y5: Programmer | Z5: Exempt CAD | AB5: E18 | AC5: E18 | AD5: AUD | AE5: 100000 | AF5: 100000 | AG5: 3 | AH5: Good | AI5: 42700 | AJ5: 61000 | AK5: 79300 | AL5: Q4 | AM5: Q4 | AO5: 5000 | AQ5: 30 | AR5: 40 | AS5: 40 | AT5: Stage meeting
A6: 2005 | B6: 2005 | C6: Leonard David | D6: Leonard David | E6: A/P Specialist | F6: Accounting% | G6: TRUE | J6: Hourly Basis | L6: Active | M6: 45767 | N6: 45767 | O6: 2001 | P6: 2001 | Q6: Brown | R6: Ward Jr Lloyd | S6: Ward Jr Lloyd | T6: 80 | U6: Jackson, Charmain | V6: 80 | W6: Jackson, Charmain | X6: J005 | Y6: Programmer | Z6: Exempt CAD | AB6: E18 | AC6: E18 | AD6: AUD | AE6: 100000 | AF6: 100000 | AG6: 1 | AH6: Poor | AI6: 42700 | AJ6: 61000 | AK6: 79300 | AL6: Q1 | AM6: Q1 | AO6: 5000 | AQ6: 30 | AR6: 40 | AS6: 40 | AT6: Stage meeting
A7: 2010 | B7: 2010 | C7: McFadden, Sarah | D7: McFadden, Sarah | E7: A/R Specialist-Billing | F7: Accounting^ | G7: T | J7: Hourly | L7: Active | M7: 45767 | N7: 45767 | O7: 2001 | P7: 2001 | Q7: Black | R7: Ward Jr Lloyd | S7: Ward Jr Lloyd | T7: 80 | U7: Jackson, Charmain | V7: 80 | W7: Jackson, Charmain | X7: J006 | Y7: Programmer | Z7: Exempt CAD | AB7: E18 | AC7: E18 | AD7: AUD | AE7: 100000 | AF7: 100000 | AG7: 5 | AH7: Good | AI7: 42700 | AJ7: 61000 | AK7: 79300 | AL7: Q2 | AM7: Q2 | AO7: 5000 | AQ7: 30 | AR7: 40 | AS7: 20 | AT7: Stage meeting
A8: 2007 | B8: 2007 | C8: Munshausen, Bruce | D8: Munshausen, Bruce | E8: HR Coordinator& | F8: Human\ Resources& | G8: t | J8: Monthly (13) | L8: Active | M8: 45767 | N8: 45767 | O8: 2001 | P8: 2001 | Q8: Brown | R8: Ward Jr Lloyd | S8: Ward Jr Lloyd | T8: 80 | U8: Jackson, Charmain | V8: 80 | W8: Jackson, Charmain | X8: J007 | Y8: Programmer | Z8: Exempt CAD | AB8: E18 | AC8: E18 | AD8: AUD | AE8: 100000 | AF8: 100000 | AG8: 3 | AH8: Good | AI8: 42700 | AJ8: 61000 | AK8: 79300 | AL8: Q3 | AM8: Q3 | AO8: 5000 | AQ8: 30 | AR8: 40 | AS8: 20 | AT8: PNL meeting
A9: 2006 | B9: 2006 | C9: Nelson III, Shawn | D9: Nelson III, Shawn | E9: HR Coordinator/AA | F9: Human Resources* | G9: 101 | J9: 13 Months | L9: Active | M9: 45767 | N9: 45767 | O9: 2001 | P9: 2001 | Q9: Brown | R9: Ward Jr Lloyd | S9: Ward Jr Lloyd | T9: 80 | U9: Jackson, Charmain | V9: 80 | W9: Jackson, Charmain | X9: J008 | Y9: Programmer | Z9: Exempt CAD | AB9: E18 | AC9: E18 | AD9: AUD | AE9: 100000 | AF9: 100000 | AG9: 3 | AH9: Good | AI9: 42700 | AJ9: 61000 | AK9: 79300 | AL9: Q4 | AM9: Q4 | AO9: 5000 | AQ9: 30 | AR9: 40 | AS9: 20 | AT9: PNL meeting
A10: 2003 | B10: 2003 | C10: Thompson, Glenn | D10: Thompson, Glenn | E10: P/R Specialist | F10: Operations( | G10: t | J10: Weekly | L10: Active | M10: 45767 | N10: 45767 | O10: s | P10: s | Q10: Red | R10: Ward Jr Lloyd | S10: Ward Jr Lloyd | T10: 80 | U10: Jackson, Charmain | V10: 80 | W10: Jackson, Charmain | X10: J009 | Y10: Programmer | Z10: Exempt CAD | AB10: E18 | AC10: E18 | AD10: AUD | AE10: 100000 | AF10: 100000 | AG10: 3 | AH10: Superior | AI10: 42700 | AJ10: 61000 | AK10: 79300 | AL10: Q1 | AM10: Q1 | AO10: 5000 | AQ10: 30 | AR10: 40 | AS10: 20 | AT10: PNL meeting
A11: 2011 | B11: 2011 | C11: Van Buskirk, Briañ | D11: Van Buskirk, Briañ | E11: Administrative Assistant I | F11: Administration) | G11: T | J11: Quaterly | L11: Active | M11: 45767 | N11: 45767 | O11: 2001 | P11: 2001 | Q11: Blond | R11: Ward Jr Lloyd | S11: Ward Jr Lloyd | T11: 80 | U11: Jackson, Charmain | V11: 80 | W11: Jackson, Charmain | X11: J010 | Y11: Programmer | Z11: Exempt CAD | AB11: E18 | AC11: E18 | AD11: AUD | AE11: 100000 | AF11: 100000 | AG11: 5 | AH11: Exceptional | AI11: 42700 | AJ11: 61000 | AK11: 79300 | AL11: Q2 | AM11: Q2 | AO11: 5000 | AQ11: 30 | AR11: 40 | AS11: 20 | AT11: PNL meeting
A12: 2012 | B12: 2012 | C12: Waguespack, Briañ | D12: Waguespack, Briañ | E12: Administrative Assistant III_ | F12: Administration_ | G12: T | J12: Half Year | L12: Active | M12: 45767 | N12: 45767 | O12: 2001 | P12: 2001 | Q12: Black | R12: Ward Jr Lloyd | S12: Ward Jr Lloyd | T12: 80 | U12: Jackson, Charmain | V12: 80 | W12: Jackson, Charmain | X12: J011 | Y12: Programmer | Z12: Exempt CAD | AB12: E18 | AC12: E18 | AD12: CAD | AE12: 100000 | AF12: 100000 | AG12: 4 | AH12: Superior | AI12: 42700 | AJ12: 61000 | AK12: 79300 | AL12: Q3 | AM12: Q3 | AO12: 5000 | AQ12: 30 | AR12: 40 | AS12: 20 | AT12: PNL meeting
A13: 2013 | B13: 2013 | C13: Yokay, James | D13: Yokay, James | E13: Director of Nursing- | F13: Operations- | G13: ON | J13: Annually | L13: Active | M13: 45767 | N13: 45767 | O13: 4545 | P13: 4545 | Q13: Grey | R13: Asif Nawaz | S13: Asif Nawaz | T13: 80 | U13: Jackson, Charmain | V13: 80 | W13: Jackson, Charmain | X13: J012 | Y13: Programmer | Z13: Exempt CAD | AB13: E18 | AC13: E18 | AD13: CAD | AE13: 100000 | AF13: 100000 | AG13: 4 | AH13: Superior | AI13: 42700 | AJ13: 61000 | AK13: 79300 | AL13: Q4 | AM13: Q4 | AO13: 5000 | AQ13: 30 | AR13: 40 | AS13: 20 | AT13: PNL meeting
A14: 94 | B14: 94 | C14: Atkinson, Tracey | D14: Atkinson, Tracey | E14: Programmer | F14: Technology+ | G14: ON | J14: Annually (1yr) | L14: Active | M14: 45767 | N14: 45767 | O14: 72 | P14: 72 | Q14: White | R14: Davis Beverly | S14: Davis Beverly | T14: 80 | U14: Jackson, Charmain | V14: 80 | W14: Jackson, Charmain | X14: J013 | Y14: Certified Nurse Aide | Z14: Exempt US | AB14: E06 | AC14: E06 | AD14: USD | AE14: 100000 | AF14: 100000 | AH14: Exceptional | AI14: 14000 | AJ14: 18600 | AK14: 22800 | AL14: Q1 | AM14: Q1 | AO14: 5000 | AQ14: 30 | AR14: 40 | AS14: 20 | AT14: Qasand meeting
A15: 73 | B15: 73 | C15: Bonamy, James | D15: Bonamy, James | E15: Accountant | F15: Accounting= | G15: on | J15: Monthly (12) | L15: Active | M15: 45767 | N15: 45767 | O15: 72 | P15: 72 | Q15: Red | R15: Davis Beverly | S15: Davis Beverly | T15: 80 | U15: Jackson, Charmain | V15: 80 | W15: Jackson, Charmain | X15: J014 | Y15: Sales/Marketing Manager | Z15: Exempt US | AB15: E30 | AC15: E30 | AD15: USD | AE15: 100000 | AF15: 100000 | AH15: Needs Improvement | AI15: 81000 | AJ15: 135000 | AK15: 189000 | AL15: Q2 | AM15: Q2 | AO15: 5000 | AQ15: 30 | AR15: 40 | AS15: 0 | AT15: Qasand meeting
A16: 88 | B16: 88 | C16: Brooks, Wendy | D16: Brooks, Wendy | E16: Bookkeeper | F16: Accounting{ | G16: ON | J16: Monthly | L16: Active | M16: 45767 | N16: 45767 | O16: 72 | P16: 72 | Q16: Red | R16: Davis Beverly | S16: Davis Beverly | T16: 80 | U16: Jackson, Charmain | V16: 80 | W16: Jackson, Charmain | X16: J015 | Y16: RN | Z16: Exempt US | AB16: E12 | AC16: E12 | AD16: USD | AE16: 100000 | AF16: 100000 | AG16: 3 | AH16: Good | AI16: 23700 | AJ16: 31500 | AK16: 39400 | AL16: Q3 | AM16: Q3 | AO16: 5000 | AQ16: 30 | AR16: 40 | AS16: 0 | AT16: Qasand meeting
A17: 91 | B17: 91 | C17: Brown, Leann | D17: Brown, Leann | E17: Development Manager | F17: Technology} | G17: on | J17: Hourly Basis | L17: Active | M17: 45767 | N17: 45767 | O17: 72 | P17: 72 | Q17: s | R17: Davis Beverly | S17: Davis Beverly | T17: 80 | U17: Jackson, Charmain | V17: 80 | W17: Jackson, Charmain | X17: J016 | Y17: LVN | Z17: Exempt US | AB17: E10 | AC17: E10 | AD17: USD | AE17: 100000 | AF17: 100000 | AG17: 3 | AH17: Good | AI17: 8000 | AJ17: 12000 | AK17: 12000 | AL17: Q4 | AM17: Q4 | AO17: 5000 | AQ17: 30 | AR17: 40 | AS17: 0 | AT17: Qasand meeting
A18: 92 | B18: 92 | C18: Craven, Liz | D18: Craven, Liz | E18: Executive Administrative Assistant | F18: Administration[ | G18: on | J18: Hourly | L18: Active | M18: 45767 | N18: 45767 | O18: 72 | P18: 72 | Q18: Brown | R18: Davis Beverly | S18: Davis Beverly | T18: 80 | U18: Jackson, Charmain | V18: 80 | W18: Jackson, Charmain | X18: J017 | Y18: LVN | Z18: Exempt US | AB18: E10 | AC18: E10 | AD18: USD | AE18: 100000 | AF18: 100000 | AG18: 3 | AH18: Good | AI18: 8000 | AJ18: 12000 | AK18: 12000 | AL18: Q1 | AM18: Q1 | AO18: 5000 | AQ18: 30 | AR18: 40 | AS18: 50 | AT18: Qasand meeting
A19: 111 | B19: 111 | C19: Galvan, Dina | D19: Galvan, Dina | E19: Project Manager | F19: Operations] | G19: on | J19: Monthly (13) | L19: Active | M19: 45767 | N19: 45767 | O19: 72 | P19: 72 | Q19: Red | R19: Davis Beverly | S19: Davis Beverly | T19: 80 | U19: Jackson, Charmain | V19: 80 | W19: Jackson, Charmain | X19: J018 | Y19: Certified Nurse Aide | Z19: Exempt US | AB19: E06 | AC19: E06 | AD19: USD | AE19: 100000 | AF19: 100000 | AG19: 1 | AH19: Poor | AI19: 14000 | AJ19: 18600 | AK19: 22800 | AL19: Q2 | AM19: Q2 | AO19: 5000 | AQ19: 30 | AR19: 40 | AS19: 50 | AT19: Qasand meeting
A20: 110 | B20: 110 | C20: Harrison, Cindy | D20: Harrison, Cindy | E20: Sr. Accountant | F20: Accounting| | G20: on | J20: 13 Months | L20: Active | M20: 45767 | N20: 45767 | O20: 72 | P20: 72 | Q20: Blond | R20: Davis Beverly | S20: Davis Beverly | T20: 80 | U20: Jackson, Charmain | V20: 80 | W20: Jackson, Charmain | X20: J019 | Y20: Certified Nurse Aide | Z20: Exempt US | AB20: E06 | AC20: E06 | AD20: USD | AE20: 100000 | AF20: 100000 | AG20: 3 | AH20: Good | AI20: 14000 | AJ20: 18600 | AK20: 22800 | AL20: Q3 | AM20: Q3 | AO20: 5000 | AQ20: 30 | AR20: 40 | AS20: 50 | AT20: Qasand meeting
A21: 95 | B21: 95 | C21: Henshaw, Candice | D21: Henshaw, Candice | E21: Human Resource Manager | F21: Human Resources\ | G21: on | J21: Weekly | L21: Active | M21: 45767 | N21: 45767 | O21: 72 | P21: 72 | Q21: Black | R21: Davis Beverly | S21: Davis Beverly | T21: 80 | U21: Jackson, Charmain | V21: 80 | W21: Jackson, Charmain | X21: J020 | Y21: Certified Nurse Aide | Z21: Exempt US | AB21: E06 | AC21: E06 | AD21: IDR | AE21: 100000 | AF21: 100000 | AG21: 3 | AH21: Good | AI21: 14000 | AJ21: 18600 | AK21: 22800 | AL21: Q4 | AM21: Q4 | AO21: 5000 | AQ21: 30 | AR21: 40 | AS21: 5.5 | AT21: Qasand meeting
A22: 80 | B22: 80 | C22: Jackson, Charmain | D22: Jackson, Charmain | E22: Sales/Marketing Manager | F22: Marketing : | G22: YES | J22: Quaterly | L22: Active | M22: 45767 | N22: 45767 | O22: 1113 | P22: 1113 | Q22: Black | R22: Davis Beverly | S22: Davis Beverly | T22: 80 | U22: Jackson, Charmain | V22: 80 | W22: Jackson, Charmain | X22: J021 | Y22: HR Coordinator | Z22: Exempt US | AB22: E14 | AC22: E14 | AD22: IDR | AE22: 100000 | AF22: 100000 | AG22: 1 | AH22: Poor | AI22: 29400 | AJ22: 42000 | AK22: 54600 | AL22: Q1 | AM22: Q1 | AO22: 5000 | AQ22: 30 | AR22: 40 | AS22: 5.5 | AT22: mikeco staf meeting
A23: 115 | B23: 115 | C23: Mathers, Paula | D23: Mathers, Paula | E23: IT Manager | F23: Technology ; | G23: YES | J23: Half Year | L23: Active | M23: 45767 | N23: 45767 | O23: 72 | P23: 72 | Q23: Brown | R23: Davis Beverly | S23: Davis Beverly | T23: 80 | U23: Jackson, Charmain | V23: 80 | W23: Jackson, Charmain | X23: J022 | Y23: Certified Nurse Aide | Z23: Exempt US | AB23: E06 | AC23: E06 | AD23: IDR | AE23: 100000 | AF23: 100000 | AG23: 3 | AH23: Good | AI23: 14000 | AJ23: 18600 | AK23: 22800 | AL23: Q2 | AM23: Q2 | AO23: 5000 | AQ23: 30 | AR23: 40 | AS23: 5.5 | AT23: mikeco staf meeting
A24: 93 | B24: 93 | C24: Mott, Michael | D24: Mott, Michael | E24: Controller' | F24: Accounting ' | G24: 1 | J24: Annually | L24: Active | M24: 45767 | N24: 45767 | O24: 72 | P24: 72 | Q24: White | R24: Davis Beverly | S24: Davis Beverly | T24: 80 | U24: Jackson, Charmain | V24: 80 | W24: Jackson, Charmain | X24: J023 | Y24: Certified Nurse Aide | Z24: Exempt US | AB24: E06 | AC24: E06 | AD24: IDR | AE24: 100000 | AF24: 100000 | AG24: 4 | AH24: Superior | AI24: 14000 | AJ24: 18600 | AK24: 22800 | AL24: Q3 | AM24: Q3 | AO24: 5000 | AQ24: 30 | AR24: 40 | AS24: 10 | AT24: mikeco staf meeting
A25: 101 | B25: 101 | C25: Napier, Alex | D25: Napier, Alex | E25: Director of HR | F25: Human Resources " | G25: 1 | J25: Annually (1yr) | L25: Active | M25: 45767 | N25: 45767 | O25: 72 | P25: 72 | Q25: Brown | R25: Davis Beverly | S25: Davis Beverly | T25: 80 | U25: Jackson, Charmain | V25: 80 | W25: Jackson, Charmain | X25: J024 | Y25: Certified Nurse Aide | Z25: Exempt US | AB25: E06 | AC25: E06 | AD25: IDR | AE25: 100000 | AF25: 100000 | AG25: 3 | AH25: Good | AI25: 14000 | AJ25: 18600 | AK25: 22800 | AL25: Q4 | AM25: Q4 | AO25: 5000 | AQ25: 30 | AR25: 40 | AS25: 10 | AT25: mikeco staf meeting
A26: 100 | B26: 100 | C26: Rames, Bill | D26: Rames, Bill | E26: Director of Operations | F26: Operations < | G26: 1 | J26: Monthly (12) | L26: Active | M26: 45767 | N26: 45767 | O26: 72 | P26: 72 | Q26: Black | R26: Davis Beverly | S26: Davis Beverly | T26: 80 | U26: Jackson, Charmain | V26: 80 | W26: Jackson, Charmain | X26: J025 | Y26: Certified Nurse Aide | Z26: Exempt US | AB26: E06 | AC26: E06 | AD26: IDR | AE26: 100000 | AF26: 100000 | AG26: 4 | AH26: Superior | AI26: 14000 | AJ26: 18600 | AK26: 22800 | AL26: Q1 | AM26: Q1 | AO26: 5000 | AQ26: 30 | AR26: 40 | AS26: 10 | AT26: mikeco staf meeting
A27: 104 | B27: 104 | C27: Risner, Elizabeth | D27: Risner, Elizabeth | E27: Director of Operations, | F27: Accounting, | G27: 0 | J27: Monthly | L27: Active | M27: 45767 | N27: 45767 | O27: 72 | P27: 72 | Q27: Brown | R27: Davis Beverly | S27: Davis Beverly | T27: 80 | U27: Jackson, Charmain | V27: 80 | W27: Jackson, Charmain | X27: J026 | Y27: Certified Nurse Aide | Z27: Exempt US | AB27: E06 | AC27: E06 | AD27: IDR | AE27: 100000 | AF27: 100000 | AG27: 2 | AH27: Needs Improvement | AI27: 14000 | AJ27: 18600 | AK27: 22800 | AL27: Q2 | AM27: Q2 | AO27: 5000 | AQ27: 30 | AR27: 40 | AS27: 10 | AT27: mikeco staf meeting
A28: 86 | B28: 86 | C28: Rogers, Mary | D28: Rogers, Mary | E28: Director of Operations | F28: Technology> | G28: N | J28: Hourly Basis | L28: Active | M28: 45767 | N28: 45767 | O28: 72 | P28: 72 | Q28: Brown | R28: Davis Beverly | S28: Davis Beverly | T28: 80 | U28: Jackson, Charmain | V28: 80 | W28: Jackson, Charmain | X28: J027 | Y28: Director of Nursing | Z28: Exempt US | AB28: E18 | AC28: E18 | AD28: IDR | AE28: 100000 | AF28: 100000 | AG28: 5 | AH28: Good | AI28: 42700 | AJ28: 61000 | AK28: 79300 | AL28: Q3 | AM28: Q3 | AO28: 5000 | AQ28: 30 | AR28: 40 | AS28: 10 | AT28: mikeco staf meeting
A29: 89 | B29: 89 | C29: White, Gordon | D29: White, Gordon | E29: Director of Operations | F29: Operations? | G29: N | J29: Hourly | L29: Active | M29: 45767 | N29: 45767 | O29: 72 | P29: 72 | Q29: Red | R29: Davis Beverly | S29: Davis Beverly | T29: 80 | U29: Jackson, Charmain | V29: 80 | W29: Jackson, Charmain | X29: J028 | Y29: RN | Z29: Exempt US | AB29: E12 | AC29: E12 | AD29: IDR | AE29: 100000 | AF29: 100000 | AG29: 4 | AH29: Superior | AI29: 23700 | AJ29: 31500 | AK29: 39400 | AL29: Q4 | AM29: Q4 | AO29: 5000 | AQ29: 30 | AR29: 40 | AS29: 10 | AT29: production staf
A30: 72 | B30: 72 | C30: Davis, Beverly | D30: Davis, Beverly | E30: Director of Operations/ | F30: Operations / | G30: n | J30: Monthly (13) | L30: Active | M30: 45767 | N30: 45767 | O30: 1012 | P30: 1012 | Q30: Blond | R30: Sherman Jack | S30: Sherman Jack | T30: 80 | U30: Jackson, Charmain | V30: 80 | W30: Jackson, Charmain | X30: J029 | Y30: Director of Operations | Z30: Exempt US | AB30: E34 | AC30: E34 | AD30: AED | AE30: 100000 | AF30: 100000 | AG30: 3 | AH30: Good | AI30: 112800 | AJ30: 188000 | AK30: 263200 | AL30: Q1 | AM30: Q1 | AO30: 5000 | AQ30: 30 | AR30: 40 | AS30: 10 | AT30: production staf
A31: 162 | B31: 162 | C31: Thompson, Calvin | D31: Thompson, Calvin | E31: Certified Doc Aide | F31: Accounting! | G31: n | J31: 13 Months | L31: Active | M31: 45767 | N31: 45767 | O31: BOD | P31: BOD | Q31: Black | R31: BOD | S31: BOD | T31: 80 | U31: Jackson, Charmain | V31: 80 | W31: Jackson, Charmain | X31: J001 | Y31: President/CEO | Z31: Exempt US | AB31: E40 | AC31: E40 | AD31: AED | AE31: 100000 | AF31: 100000 | AG31: 3 | AH31: Good | AI31: 192000 | AJ31: 320000 | AK31: 448000 | AL31: Q2 | AM31: Q2 | AO31: 5000 | AQ31: 30 | AR31: 40 | AS31: 10 | AT31: production staf
A32: 1121 | B32: 1121 | C32: Masters, Sarah | D32: Masters, Sarah | E32: Certified Nurse Aide | F32: Operations@ | G32: n | J32: Weekly | L32: Active | M32: 45767 | N32: 45767 | O32: 1113 | P32: 1113 | Q32: Black | R32: Duncan Sam | S32: Duncan Sam | T32: 80 | U32: Jackson, Charmain | V32: 80 | W32: Jackson, Charmain | X32: J002 | Y32: Director of Nursing | Z32: Exempt US | AB32: E18 | AC32: E18 | AD32: AED | AE32: 100000 | AF32: 100000 | AG32: 5 | AH32: Exceptional | AI32: 42700 | AJ32: 61000 | AK32: 79300 | AL32: Q3 | AM32: Q3 | AO32: 5000 | AQ32: 30 | AR32: 40 | AS32: 10 | AT32: production staf
A33: 1117 | B33: 1117 | C33: Ramsey, Richele | D33: Ramsey, Richele | E33: LVN | F33: Operations# | G33: NO | J33: Quaterly | L33: Active | M33: 45767 | N33: 45767 | O33: 1113 | P33: 1113 | Q33: Brown | R33: Duncan Sam | S33: Duncan Sam | T33: 80 | U33: Jackson, Charmain | V33: 80 | W33: Jackson, Charmain | X33: J003 | Y33: HR Coordinator/AA | Z33: Exempt US | AB33: E14 | AC33: E14 | AD33: AED | AE33: 100000 | AF33: 100000 | AG33: 5 | AH33: Exceptional | AI33: 29400 | AJ33: 42000 | AK33: 54600 | AL33: Q4 | AM33: Q4 | AO33: 5000 | AQ33: 30 | AR33: 40 | AS33: 10 | AT33: production staf
A34: 1115 | B34: 1115 | C34: Ross, Michael | D34: Ross, Michael | E34: RN | F34: Operations$ | G34: NO | J34: Half Year | L34: Active | M34: 45767 | N34: 45767 | O34: 1113 | P34: 1113 | Q34: Brown | R34: Duncan Sam | S34: Duncan Sam | T34: 80 | U34: Jackson, Charmain | V34: 80 | W34: Jackson, Charmain | X34: J004 | Y34: Sales/Marketing Manager | Z34: Exempt US | AB34: E30 | AC34: E30 | AD34: USD | AE34: 100000 | AF34: 100000 | AG34: 4 | AH34: Superior | AI34: 81000 | AJ34: 135000 | AK34: 189000 | AL34: Q1 | AM34: Q1 | AO34: 5000 | AQ34: 30 | AR34: 40 | AS34: 10 | AT34: production staf
A35: 1128 | B35: 1128 | C35: Hinze, Drea | D35: Hinze, Drea | E35: A/P Specialist | F35: Accounting% | G35: NO | J35: Annually | L35: Active | M35: 45767 | N35: 45767 | O35: 1121 | P35: 1121 | Q35: Black | R35: Masters Sarah | S35: Masters Sarah | T35: 80 | U35: Jackson, Charmain | V35: 80 | W35: Jackson, Charmain | X35: J005 | Y35: Certified Nurse Aide | Z35: Exempt US | AB35: E06 | AC35: E06 | AD35: AED | AE35: 100000 | AF35: 100000 | AG35: 3 | AH35: Good | AI35: 14000 | AJ35: 18600 | AK35: 22800 | AL35: Q2 | AM35: Q2 | AO35: 5000 | AQ35: 30 | AR35: 40 | AS35: 10 | AT35: production staf
A36: 1123 | B36: 1123 | C36: Jackson, Leah | D36: Jackson, Leah | E36: A/R Specialist-Billing | F36: Accounting^ | G36: no | J36: Annually (1yr) | L36: Active | M36: 45767 | N36: 45767 | O36: 1121 | P36: 1121 | Q36: Brown | R36: Masters Sarah | S36: Masters Sarah | T36: 80 | U36: Jackson, Charmain | V36: 80 | W36: Jackson, Charmain | X36: J006 | Y36: LVN | Z36: Exempt US | AB36: E10 | AC36: E10 | AD36: AED | AE36: 100000 | AF36: 100000 | AG36: 2 | AH36: Needs Improvement | AI36: 8000 | AJ36: 12000 | AK36: 12000 | AL36: Q3 | AM36: Q3 | AO36: 5000 | AQ36: 30 | AR36: 40 | AS36: 10 | AT36: production staf
A37: 70 | B37: 70 | C37: Kirklan, Richard | D37: Kirklan, Richard | E37: HR Coordinator& | F37: Human\ Resources& | G37: no | J37: Monthly (12) | L37: Active | M37: 45767 | N37: 45767 | O37: 1121 | P37: 1121 | Q37: Brown | R37: Masters Sarah | S37: Masters Sarah | T37: 1117 | U37: Ramsey, Richele | V37: 80 | W37: Jackson, Charmain | X37: J007 | Y37: Certified Nurse Aide | Z37: Exempt US | AB37: E06 | AC37: E06 | AD37: AED | AE37: 100000 | AF37: 100000 | AG37: 3 | AH37: Good | AI37: 14000 | AJ37: 18600 | AK37: 22800 | AL37: Q4 | AM37: Q4 | AO37: 5000 | AQ37: 30 | AR37: 40 | AS37: 10 | AT37: production staf
A38: 1119 | B38: 1119 | C38: Mills, Gavin | D38: Mills, Gavin | E38: HR Coordinator/AA | F38: Human Resources* | G38: no | J38: Monthly | L38: Active | M38: 45767 | N38: 45767 | O38: 1121 | P38: 1121 | Q38: Red | R38: Masters Sarah | S38: Masters Sarah | T38: 1117 | U38: Ramsey, Richele | V38: 80 | W38: Jackson, Charmain | X38: J008 | Y38: RN | Z38: Exempt US | AB38: E12 | AC38: E12 | AD38: GBP | AE38: 100000 | AF38: 100000 | AG38: 3 | AH38: Good | AI38: 23700 | AJ38: 31500 | AK38: 39400 | AL38: Q1 | AM38: Q1 | AO38: 5000 | AQ38: 30 | AR38: 40 | AS38: 10 | AT38: production staf
A39: 1118 | B39: 1118 | C39: Perez, Leila | D39: Perez, Leila | E39: P/R Specialist | F39: Operations( | G39: OFF | J39: Hourly Basis | L39: Active | M39: 45767 | N39: 45767 | O39: 1121 | P39: 1121 | Q39: Blond | R39: Masters Sarah | S39: Masters Sarah | T39: 1117 | U39: Ramsey, Richele | V39: 80 | W39: Jackson, Charmain | X39: J009 | Y39: RN | Z39: Exempt US | AB39: E12 | AC39: E12 | AD39: GBP | AE39: 100000 | AF39: 100000 | AG39: 3 | AH39: Good | AI39: 23700 | AJ39: 31500 | AK39: 39400 | AL39: Q2 | AM39: Q2 | AO39: 5000 | AQ39: 30 | AR39: 40 | AS39: 10 | AT39: production staf
A40: 59 | B40: 59 | C40: Sanders, Lynn | D40: Sanders, Lynn | E40: Administrative Assistant I | F40: Administration) | G40: OFF | J40: Hourly | L40: Active | M40: 45767 | N40: 45767 | O40: 1121 | P40: 1121 | Q40: Black | R40: Masters Sarah | S40: Masters Sarah | T40: 1117 | U40: Ramsey, Richele | V40: 80 | W40: Jackson, Charmain | X40: J010 | Y40: Certified Nurse Aide | Z40: Exempt US | AB40: E06 | AC40: E06 | AD40: GBP | AE40: 100000 | AF40: 100000 | AG40: 4 | AH40: Superior | AI40: 14000 | AJ40: 18600 | AK40: 22800 | AL40: Q3 | AM40: Q3 | AO40: 5000 | AQ40: 30 | AR40: 40 | AS40: 10 | AT40: production staf
...

Sheet Employee Bonus Plans
A1: Employee Id | B1: Emp Id | C1: Name | D1: Bonus Plan Name | E1: Employee Name | F1: Prorated Bonus Mult Pct | G1: Mgr Emp Id | H1: Manager Name | I1: Plan Mgr Emp Id | J1: Plan Mgr Emp Name | K1: Salary | L1: Eligible Earnings | M1: Base Amount | N1: Bonus Calc Base Amt | O1: Currency Code | P1: Bonus From Date | Q1: Bonus To Date | S1: Proration % | T1: Bonus Target | U1: Tgt Opp Pct | V1: Target % | W1: Tgt Opp Amt | X1: Bonus Guar Min Amt | Y1: Bonus Guideline Min Amt | Z1: Bonus Guideline Tgt Amt | AA1: Bonus Guideline Max Amt | AB1: Prepaid Amt | AC1: Aziz Hair color | AD1: Bonus User Def 1 Amt | AE1: Job Title
A2: 2009 | B2: 2009 | C2: Grimm, Briañ | D2: B1 | E2: Grimm, Briañ | F2: 1 | G2: 72 | H2: Davis, Beverly | K2: 100000 | L2: 100000 | M2: 100000 | N2: 100000 | O2: AED | P2: 45767 | Q2: 46022 | S2: 1 | T2: 0.2 | U2: 0.2 | V2: 0.2 | W2: 40000 | Y2: 15000 | Z2: 30000 | AA2: 45000 | AB2: 5000 | AC2: White | AD2: 10 | AE2: Software engineer/XXXX
A3: 2004 | B3: 2004 | C3: Janish, Betty | D3: B1 | E3: Janish, Betty | F3: 1 | G3: 72 | H3: Davis, Beverly | K3: 100000 | L3: 100000 | M3: 100000 | N3: 100000 | O3: AED | P3: 45767 | Q3: 46022 | S3: 1 | T3: 0.2 | U3: 0.2 | V3: 0.2 | W3: 40000 | X3: 15000 | Y3: 15000 | Z3: 30000 | AA3: 45000 | AB3: 5000 | AC3: White | AD3: 11 | AE3: Software engineer/XXXX
A4: 2002 | B4: 2002 | C4: Keeling, Larry | D4: B1 | E4: Keeling, Larry | F4: 1 | G4: 72 | H4: Davis, Beverly | K4: 100000 | L4: 100000 | M4: 100000 | N4: 100000 | O4: AED | P4: 45767 | Q4: 46022 | S4: 1 | T4: 0.2 | U4: 0.2 | V4: 0.2 | W4: 40000 | Y4: 15000 | Z4: 30000 | AA4: 45000 | AB4: 5000 | AC4: White | AD4: 12 | AE4: Software engineer/XXXX
A5: 2008 | B5: 2008 | C5: Krendick Jasoñ | D5: B1 | E5: Krendick Jasoñ | F5: 1 | G5: 72 | H5: Davis, Beverly | K5: 100000 | L5: 100000 | M5: 100000 | N5: 100000 | O5: AED | P5: 45767 | Q5: 46022 | S5: 1 | T5: 0.2 | U5: 0.2 | V5: 0.2 | W5: 40000 | Y5: 15000 | Z5: 30000 | AA5: 45000 | AB5: 5000 | AC5: White | AD5: 13 | AE5: Software engineer/XXXX
A6: 2005 | B6: 2005 | C6: Leonard, David | D6: B1 | E6: Leonard, David | F6: 1 | G6: 72 | H6: Davis, Beverly | K6: 100000 | L6: 100000 | M6: 100000 | N6: 100000 | O6: AED | P6: 45767 | Q6: 46022 | S6: 1 | T6: 0.2 | U6: 0.2 | V6: 0.2 | W6: 40000 | Y6: 15000 | Z6: 30000 | AA6: 45000 | AB6: 5000 | AC6: White | AD6: 14 | AE6: Software engineer/XXXX
A7: 2010 | B7: 2010 | C7: McFadden, Sarah | D7: B1 | E7: McFadden, Sarah | F7: 1 | G7: 72 | H7: Davis, Beverly | K7: 100000 | L7: 100000 | M7: 100000 | N7: 100000 | O7: AED | P7: 45767 | Q7: 46022 | S7: 1 | T7: 0.2 | U7: 0.2 | V7: 0.2 | W7: 40000 | Y7: 15000 | Z7: 30000 | AA7: 45000 | AB7: 5000 | AC7: White | AD7: 15 | AE7: Software engineer/XXXX
A8: 2007 | B8: 2007 | C8: Munshausen, Bruce | D8: B1 | E8: Munshausen, Bruce | F8: 1 | G8: 72 | H8: Davis, Beverly | K8: 100000 | L8: 100000 | M8: 100000 | N8: 100000 | O8: AED | P8: 45767 | Q8: 46022 | S8: 1 | T8: 0.2 | U8: 0.2 | V8: 0.2 | W8: 40000 | Y8: 15000 | Z8: 30000 | AA8: 45000 | AB8: 5000 | AC8: White | AD8: 16 | AE8: Software engineer/XXXX
A9: 2006 | B9: 2006 | C9: Nelson III, Shawn | D9: B1 | E9: Nelson III, Shawn | F9: 1 | G9: 72 | H9: Davis, Beverly | K9: 100000 | L9: 100000 | M9: 100000 | N9: 100000 | O9: AED | P9: 45767 | Q9: 46022 | S9: 1 | T9: 0.2 | U9: 0.2 | V9: 0.2 | W9: 40000 | X9: 25000 | Y9: 15000 | Z9: 30000 | AA9: 45000 | AB9: 5000 | AC9: White | AD9: 17 | AE9: Software engineer/XXXX
A10: 2003 | B10: 2003 | C10: Thompson, Glenn | D10: B1 | E10: Thompson, Glenn | F10: 1 | G10: 72 | H10: Davis, Beverly | K10: 100000 | L10: 100000 | M10: 100000 | N10: 100000 | O10: USD | P10: 45767 | Q10: 46022 | S10: 1 | T10: 0.2 | U10: 0.2 | V10: 0.2 | W10: 40000 | Y10: 15000 | Z10: 30000 | AA10: 45000 | AB10: 5000 | AC10: White | AD10: 18 | AE10: Software engineer/XXXX
A11: 2011 | B11: 2011 | C11: Van Buskirk, Briañ | D11: B1 | E11: Van Buskirk, Briañ | F11: 1 | G11: 72 | H11: Davis, Beverly | K11: 100000 | L11: 100000 | M11: 100000 | N11: 100000 | O11: USD | P11: 45767 | Q11: 46022 | S11: 1 | T11: 0.2 | U11: 0.2 | V11: 0.2 | W11: 40000 | Y11: 15000 | Z11: 30000 | AA11: 45000 | AB11: 5000 | AC11: White | AD11: 19 | AE11: Software engineer/XXXX
A12: 2012 | B12: 2012 | C12: Waguespack, Briañ | D12: B1 | E12: Waguespack, Briañ | F12: 1 | G12: 72 | H12: Davis, Beverly | K12: 100000 | L12: 100000 | M12: 100000 | N12: 100000 | O12: USD | P12: 45767 | Q12: 46022 | S12: 1 | T12: 0.2 | U12: 0.2 | V12: 0.2 | W12: 40000 | Y12: 15000 | Z12: 30000 | AA12: 45000 | AB12: 5000 | AC12: White | AD12: 20 | AE12: Software engineer/XXXX
A13: 2013 | B13: 2013 | C13: Yokay, James | D13: B1 | E13: Yokay, James | F13: 1 | K13: 100000 | L13: 100000 | M13: 100000 | N13: 100000 | O13: USD | P13: 45767 | Q13: 46022 | S13: 1 | T13: 0.2 | U13: 0.2 | V13: 0.2 | W13: 40000 | Y13: 15000 | Z13: 30000 | AA13: 45000 | AB13: 5000 | AC13: White | AD13: 21 | AE13: Software engineer/XXXX
A14: 94 | B14: 94 | C14: Atkinson, Tracey | D14: B1 | E14: Atkinson, Tracey | K14: 100000 | L14: 100000 | M14: 100000 | N14: 100000 | O14: USD | P14: 45767 | Q14: 46022 | T14: 0.2 | U14: 0.2 | V14: 0.2 | W14: 40000 | X14: 30000 | Y14: 15000 | Z14: 30000 | AA14: 45000 | AB14: 5000 | AC14: Black | AD14: 22 | AE14: Software engineer/XXXX
A15: 73 | B15: 73 | C15: Bonamy, James | D15: B1 | E15: Bonamy, James | F15: 1 | K15: 100000 | L15: 100000 | M15: 100000 | N15: 100000 | O15: USD | P15: 45767 | Q15: 46022 | S15: 1 | T15: 0.2 | U15: 0.2 | V15: 0.2 | W15: 40000 | Y15: 15000 | Z15: 30000 | AA15: 45000 | AB15: 5000 | AC15: Black | AD15: 23 | AE15: QA/xx
A16: 88 | B16: 88 | C16: Brooks, Wendy | D16: B1 | E16: Brooks, Wendy | F16: 1 | K16: 100000 | L16: 100000 | M16: 100000 | N16: 100000 | O16: USD | P16: 45767 | Q16: 46022 | S16: 1 | T16: 0.2 | U16: 0.2 | V16: 0.2 | W16: 40000 | Y16: 15000 | Z16: 30000 | AA16: 45000 | AB16: 5000 | AC16: Black | AD16: 24 | AE16: QA/xx
A17: 91 | B17: 91 | C17: Brown, Leann | D17: B1 | E17: Brown, Leann | F17: 1 | K17: 100000 | L17: 100000 | M17: 100000 | N17: 100000 | O17: USD | P17: 45767 | Q17: 46022 | S17: 1 | T17: 0.2 | U17: 0.2 | V17: 0.2 | W17: 40000 | Y17: 15000 | Z17: 30000 | AA17: 45000 | AB17: 5000 | AC17: Black | AD17: test | AE17: QA/xx
A18: 92 | B18: 92 | C18: Craven, Liz | D18: B1 | E18: Craven, Liz | F18: 1 | K18: 100000 | L18: 100000 | M18: 100000 | N18: 100000 | O18: CAD | P18: 45767 | Q18: 46022 | S18: 1 | T18: 0.2 | U18: 0.2 | V18: 0.2 | W18: 40000 | X18: 45000 | Y18: 15000 | Z18: 30000 | AA18: 45000 | AB18: 5000 | AC18: Black | AD18: ok | AE18: QA/xx
A19: 111 | B19: 111 | C19: Galvan, Dina | D19: B1 | E19: Galvan, Dina | F19: 1 | K19: 100000 | L19: 100000 | M19: 100000 | N19: 100000 | O19: CAD | P19: 45767 | Q19: 46022 | S19: 1 | T19: 0.2 | U19: 0.2 | V19: 0.2 | W19: 40000 | Y19: 15000 | Z19: 30000 | AA19: 45000 | AB19: 5000 | AC19: Black | AD19: "50" | AE19: QA/xx
A20: 110 | B20: 110 | C20: Harrison, Cindy | D20: B1 | E20: Harrison, Cindy | F20: 1 | K20: 100000 | L20: 100000 | M20: 100000 | N20: 100000 | O20: CAD | P20: 45767 | Q20: 46022 | S20: 1 | T20: 0.2 | U20: 0.2 | V20: 0.2 | W20: 40000 | Y20: 15000 | Z20: 30000 | AA20: 45000 | AB20: 5000 | AC20: Black | AD20: "50" | AE20: QA/xx
A21: 95 | B21: 95 | C21: Henshaw, Candice | D21: B1 | E21: Henshaw, Candice | F21: 0.5 | K21: 100000 | L21: 100000 | M21: 100000 | N21: 100000 | O21: CAD | P21: 45767 | Q21: 46022 | S21: 1 | T21: 0.2 | U21: 0.2 | V21: 0.2 | W21: 40000 | X21: 50000 | Y21: 15000 | Z21: 30000 | AA21: 45000 | AB21: 5000 | AC21: Black | AD21: "50" | AE21: QA/xx
A22: 80 | B22: 80 | C22: Jackson, Charmain | D22: B1 | E22: Jackson, Charmain | F22: 1 | K22: 100000 | L22: 100000 | M22: 100000 | N22: 100000 | O22: CAD | P22: 45767 | Q22: 46022 | S22: 1 | T22: 0.2 | U22: 0.2 | V22: 0.2 | W22: 40000 | Y22: 15000 | Z22: 30000 | AA22: 45000 | AB22: 5000 | AC22: Black | AD22: "50" | AE22: QA/xx
A23: 115 | B23: 115 | C23: Mathers, Paula | D23: B1 | E23: Mathers, Paula | F23: 1 | K23: 100000 | L23: 100000 | M23: 100000 | N23: 100000 | O23: CAD | P23: 45767 | Q23: 46022 | S23: 1 | T23: 0.2 | U23: 0.2 | V23: 0.2 | W23: 40000 | Y23: 15000 | Z23: 30000 | AA23: 45000 | AB23: 5000 | AC23: Black | AD23: "50" | AE23: QA/xx
A24: 93 | B24: 93 | C24: Mott, Michael | D24: B1 | E24: Mott, Michael | F24: 1 | K24: 100000 | L24: 100000 | M24: 100000 | N24: 100000 | O24: BRL | P24: 45767 | Q24: 46022 | S24: 1 | T24: 0.2 | U24: 0.2 | V24: 0.2 | W24: 40000 | Y24: 15000 | Z24: 30000 | AA24: 45000 | AB24: 5000 | AC24: Black | AD24: "50" | AE24: QA/xx
A25: 101 | B25: 101 | C25: Napier, Alex | D25: B1 | E25: Napier, Alex | F25: 1 | K25: 100000 | L25: 100000 | M25: 100000 | N25: 100000 | O25: BRL | P25: 45767 | Q25: 46022 | S25: 1 | T25: 0.2 | U25: 0.2 | V25: 0.2 | W25: 40000 | Y25: 15000 | Z25: 30000 | AA25: 45000 | AB25: 5000 | AC25: Black | AD25: "50" | AE25: QA/xx
A26: 100 | B26: 100 | C26: Rames, Bill | D26: B1 | E26: Rames, Bill | F26: 0.7 | K26: 100000 | L26: 100000 | M26: 100000 | N26: 100000 | O26: BRL | P26: 45767 | Q26: 46022 | S26: 0.7 | T26: 0.2 | U26: 0.2 | V26: 0.2 | W26: 40000 | Y26: 15000 | Z26: 30000 | AA26: 45000 | AB26: 5000 | AC26: Black | AD26: 40.5 | AE26: QA/xx
A27: 104 | B27: 104 | C27: Risner, Elizabeth | D27: B1 | E27: Risner, Elizabeth | F27: 1 | K27: 100000 | L27: 100000 | M27: 100000 | N27: 100000 | O27: BRL | P27: 45767 | Q27: 46022 | S27: 1 | T27: 0.2 | U27: 0.2 | V27: 0.2 | W27: 40000 | Y27: 15000 | Z27: 30000 | AA27: 45000 | AB27: 5000 | AC27: Black | AD27: 41.5 | AE27: QA/xx
A28: 86 | B28: 86 | C28: Rogers, Mary | D28: B1 | E28: Rogers, Mary | F28: 1 | K28: 100000 | L28: 100000 | M28: 100000 | N28: 100000 | O28: BRL | P28: 45767 | Q28: 46022 | S28: 1 | T28: 0.2 | U28: 0.2 | V28: 0.2 | W28: 40000 | X28: 40000 | Y28: 15000 | Z28: 30000 | AA28: 45000 | AB28: 5000 | AC28: Black | AD28: 42.5 | AE28: QA/xx
A29: 89 | B29: 89 | C29: White, Gordon | D29: B1 | E29: White, Gordon | F29: 1 | K29: 100000 | L29: 100000 | M29: 100000 | N29: 100000 | O29: IDR | P29: 45767 | Q29: 46022 | S29: 1 | T29: 0.2 | U29: 0.2 | V29: 0.2 | W29: 40000 | Y29: 15000 | Z29: 30000 | AA29: 45000 | AB29: 5000 | AC29: Brown | AD29: 43.5 | AE29: QA/xx
A30: 72 | B30: 72 | C30: Davis, Beverly | D30: B1 | E30: Davis, Beverly | F30: 1 | K30: 100000 | L30: 100000 | M30: 100000 | N30: 100000 | O30: IDR | P30: 45767 | Q30: 46022 | S30: 1 | T30: 0.2 | U30: 0.2 | V30: 0.2 | W30: 40000 | Y30: 15000 | Z30: 30000 | AA30: 45000 | AB30: 5000 | AC30: Brown | AD30: 44.5 | AE30: QA/xx
A31: 162 | B31: 162 | C31: Thompson, Calvin | D31: B1 | E31: Thompson, Calvin | F31: 1 | K31: 100000 | L31: 100000 | M31: 100000 | N31: 100000 | O31: IDR | P31: 45767 | Q31: 46022 | S31: 1 | T31: 0.2 | U31: 0.2 | V31: 0.2 | W31: 40000 | Y31: 15000 | Z31: 30000 | AA31: 45000 | AB31: 5000 | AC31: Brown | AD31: 45.5 | AE31: Accountant/xxx
A32: 1121 | B32: 1121 | C32: Masters, Sarah | D32: B1 | E32: Masters, Sarah | F32: 1 | K32: 100000 | L32: 100000 | M32: 100000 | N32: 100000 | O32: IDR | P32: 45767 | Q32: 46022 | S32: 1 | T32: 0.2 | U32: 0.2 | V32: 0.2 | W32: 40000 | Y32: 15000 | Z32: 30000 | AA32: 45000 | AB32: 5000 | AC32: Brown | AD32: 46.5 | AE32: Accountant/xxx
A33: 1117 | B33: 1117 | C33: Ramsey, Richele | D33: B1 | E33: Ramsey, Richele | F33: 1 | K33: 100000 | L33: 100000 | M33: 100000 | N33: 100000 | O33: IDR | P33: 45767 | Q33: 46022 | S33: 1 | T33: 0.2 | U33: 0.2 | V33: 0.2 | W33: 40000 | Y33: 15000 | Z33: 30000 | AA33: 45000 | AB33: 5000 | AC33: Brown | AD33: 47.5 | AE33: Accountant/xxx
A34: 1115 | B34: 1115 | C34: Ross, Michael | D34: B1 | E34: Ross, Michael | K34: 100000 | L34: 100000 | M34: 100000 | N34: 100000 | O34: IDR | P34: 45767 | Q34: 46022 | S34: 1 | T34: 0.2 | U34: 0.2 | V34: 0.2 | W34: 40000 | X34: 145000 | Y34: 15000 | Z34: 30000 | AA34: 45000 | AB34: 5000 | AC34: Brown | AD34: 48.5 | AE34: Accountant/xxx
A35: 1128 | B35: 1128 | C35: Hinze, Drea | D35: B1 | E35: Hinze, Drea | K35: 100000 | L35: 100000 | M35: 100000 | N35: 100000 | O35: IDR | P35: 45767 | Q35: 46022 | S35: 1 | T35: 0.2 | U35: 0.2 | V35: 0.2 | W35: 40000 | Y35: 15000 | Z35: 30000 | AA35: 45000 | AB35: 5000 | AC35: Brown | AD35: 49.5 | AE35: Accountant/xxx
A36: 1123 | B36: 1123 | C36: Jackson, Leah | D36: B1 | E36: Jackson, Leah | K36: 100000 | L36: 100000 | M36: 100000 | N36: 100000 | O36: IDR | P36: 45767 | Q36: 46022 | S36: 1 | T36: 0.2 | U36: 0.2 | V36: 0.2 | W36: 40000 | Y36: 15000 | Z36: 30000 | AA36: 45000 | AB36: 5000 | AC36: 1 | AD36: 50.5 | AE36: Accountant/xxx
A37: 70 | B37: 70 | C37: Kirklan, Richard | D37: B1 | E37: Kirklan, Richard | K37: 100000 | L37: 100000 | M37: 100000 | N37: 100000 | O37: USD | P37: 45767 | Q37: 46022 | S37: 1 | T37: 0.2 | U37: 0.2 | V37: 0.2 | W37: 40000 | Y37: 15000 | Z37: 30000 | AA37: 45000 | AB37: 5000 | AC37: 2 | AD37: 51.5 | AE37: Accountant/xxx
A38: 1119 | B38: 1119 | C38: Mills, Gavin | D38: B1 | E38: Mills, Gavin | K38: 100000 | L38: 100000 | M38: 100000 | N38: 100000 | O38: USD | P38: 45767 | Q38: 46022 | S38: 1 | T38: 0.2 | U38: 0.2 | V38: 0.2 | W38: 40000 | Y38: 15000 | Z38: 30000 | AA38: 45000 | AB38: 5000 | AC38: Brown | AD38: 52.5 | AE38: Accountant/xxx
A39: 1118 | B39: 1118 | C39: Perez, Leila | D39: B1 | E39: Perez, Leila | K39: 100000 | L39: 100000 | M39: 100000 | N39: 100000 | O39: USD | P39: 45767 | Q39: 46022 | S39: 1 | T39: 0.2 | U39: 0.2 | V39: 0.2 | W39: 40000 | Y39: 15000 | Z39: 30000 | AA39: 45000 | AB39: 5000 | AC39: Brown | AD39: 53.5 | AE39: Accountant/xxx
A40: 59 | B40: 59 | C40: Sanders, Lynn | D40: B1 | E40: Sanders, Lynn | K40: 100000 | L40: 100000 | M40: 100000 | N40: 100000 | O40: USD | P40: 45767 | Q40: 46022 | S40: 1 | T40: 0.2 | U40: 0.2 | V40: 0.2 | W40: 40000 | X40: 50000 | Y40: 15000 | Z40: 30000 | AA40: 45000 | AB40: 5000 | AC40: Brown | AD40: 54.5 | AE40: Accountant/xxx
...

Sheet Employee LTI Plans
A1: Employee Id | B1: Emp Id | C1: Name | D1: Employee Name | E1: Prorated LTI Mult Pct | F1: LTI Plan Name | G1: LTI Base Amt | H1: Currency Code | I1: LTI From Date | J1: LTI To Date | K1: Tgt LTI Opp Pct | L1: LTI Target | M1: Tgt LTI Opp Amt | N1: Mgr Emp Id | O1: Manager Name | P1: Plan Mgr Emp Id | Q1: Plan Mgr Emp Name | S1: LTI Guaranteed Minimum Amt | T1: Prior Grant Shares | U1: Prior Grant Value | V1: Bag Color | W1: Bag No | X1: Shoes Collection | Y1: Hair color | Z1: Sapphire | AA1: LTI Guideline Tgt Amt | AB1: LTI Guideline Min AmtX | AC1: LTI Guideline Max AmtX
A2: 161 | B2: 161 | C2: Butler, Cathy | D2: Butler, Cathy | E2: 1 | F2: L1 | G2: 100000 | H2: AED | I2: 45767 | J2: 46022 | K2: 0.1 | L2: 20000 | M2: 20000 | S2: 35000 | T2: 40 | U2: 10000 | V2: s | W2: 4 | X2: Bata shoes | Y2: 8.5 | Z2: summer collection | AB2: 15000 | AC2: 45000
A3: 167 | B3: 167 | C3: Ramos, Amy | D3: Ramos, Amy | E3: 1 | F3: L1 | G3: 100000 | H3: AED | I3: 45767 | J3: 46022 | K3: 0.1 | L3: 20000 | M3: 20000 | T3: 41 | U3: 10000 | V3: Black | W3: 5 | X3: ECS shoes | Y3: 9.5 | Z3: summer collection | AB3: 15000 | AC3: 45000
A4: 86 | B4: 86 | C4: Rogers, Mary | D4: Rogers, Mary | E4: 1 | F4: L1 | G4: 100000 | H4: USD | I4: 45767 | J4: 46022 | K4: 0.1 | L4: 20000 | M4: 20000 | T4: 45 | U4: 55890 | V4: off white | W4: 9 | X4: ECS shoes | Y4: 13.5 | Z4: summer collection | AB4: 15000 | AC4: 45000
A5: 1121 | B5: 1121 | C5: Masters, Sarah | D5: Masters, Sarah | E5: 1 | F5: L1 | G5: 100000 | H5: USD | I5: 45767 | J5: 46022 | K5: 0.1 | L5: 20000 | M5: 20000 | S5: 25000 | T5: 47 | U5: 55890 | V5: ss | W5: 11 | X5: ECS shoes | Y5: 15.5 | Z5: summer collection | AB5: 15000 | AC5: 45000
A6: 72 | B6: 72 | C6: Davis, Beverly | D6: Davis, Beverly | E6: 1 | F6: L1 | G6: 100000 | H6: USD | I6: 45767 | J6: 46022 | K6: 0.1 | L6: 20000 | M6: 20000 | T6: 48 | U6: 55890 | V6: off white | W6: 12 | X6: ECS shoes | Y6: 16.5 | Z6: summer collection | AB6: 15000 | AC6: 45000
A7: 162 | B7: 162 | C7: Thompson, Calvin | D7: Thompson, Calvin | E7: 1 | F7: L1 | G7: 100000 | H7: CAD | I7: 45767 | J7: 46022 | K7: 0.1 | L7: 20000 | M7: 20000 | S7: 25000 | T7: 55 | U7: 55890 | V7: off white | W7: test | X7: Service shoes | Y7: 23.5 | Z7: summer collection | AB7: 15000 | AC7: 45000
A8: 73 | B8: 73 | C8: Bonamy, James | D8: Bonamy, James | E8: 1 | F8: L1 | G8: 100000 | H8: CAD | I8: 45767 | J8: 46022 | K8: 0.1 | L8: 20000 | M8: 20000 | T8: 50.65 | U8: 55890 | V8: off white | W8: test | X8: Service shoes | Y8: 25.5 | Z8: summer collection | AB8: 15000 | AC8: 45000
A9: 1113 | B9: 1113 | C9: Duncan, Sam | D9: Duncan, Sam | E9: 1 | F9: L1 | G9: 100000 | H9: BRL | I9: 45767 | J9: 46022 | K9: 0.1 | L9: 20000 | M9: 20000 | S9: 30000 | T9: 60123 | U9: 55890 | V9: Black | W9: 10.5 | X9: Heels shoes | Y9: 28.5 | Z9: winter collection | AB9: 15000 | AC9: 45000
A10: 2004 | B10: 2004 | C10: Janish, Betty | D10: Janish, Betty | E10: 1 | F10: L1 | G10: 100000 | H10: BRL | I10: 45767 | J10: 46022 | K10: 0.1 | L10: 20000 | M10: 20000 | N10: 1113 | O10: Duncan Sam | T10: 60123 | U10: 55890 | V10: Black | W10: 10.5 | X10: Heels shoes | Y10: 29.5 | Z10: winter collection | AB10: 15000 | AC10: 45000
A11: 2002 | B11: 2002 | C11: Keeling, Larry | D11: Keeling, Larry | E11: 1 | F11: L1 | G11: 100000 | H11: BRL | I11: 45767 | J11: 46022 | K11: 0.1 | L11: 20000 | M11: 20000 | N11: 1113 | O11: Duncan Sam | S11: 15000 | T11: 60123 | U11: 55890 | V11: Black | W11: s | X11: Heels shoes | Y11: 30.5 | Z11: winter collection | AB11: 15000 | AC11: 45000
A12: 166 | B12: 166 | C12: Montana, Joe | D12: Montana, Joe | E12: 1 | F12: L1 | G12: 100000 | H12: IDR | I12: 45767 | J12: 46022 | K12: 0.1 | L12: 20000 | M12: 20000 | T12: 60123 | U12: 55890 | V12: Black | W12: 10.5 | X12: Heels shoes | Y12: 32.5 | Z12: winter collection | AB12: 15000 | AC12: 45000
A13: 177 | B13: 177 | C13: Pope, Ian | D13: Pope, Ian | F13: L1 | G13: 100000 | H13: IDR | I13: 45767 | J13: 46022 | K13: 0.1 | L13: 20000 | M13: 20000 | S13: 20000 | T13: 60123 | U13: 55890 | V13: Black | W13: 10.5 | X13: Heels shoes | Y13: 10.5 | Z13: winter collection | AB13: 15000 | AC13: 45000
A14: 1115 | B14: 1115 | C14: Ross, Michael | D14: Ross, Michael | F14: L1 | G14: 100000 | H14: USD | I14: 45767 | J14: 46022 | K14: 0.1 | L14: 20000 | M14: 20000 | S14: 70000 | T14: 60 | U14: 55890 | V14: Black | W14: 15.11 | X14: 1 | Y14: 13.5 | Z14: Bridal dress | AB14: 15000 | AC14: 45000
A15: 1114 | B15: 1114 | C15: Sampson, DeDe | D15: Sampson, DeDe | F15: L1 | G15: 100000 | H15: IDR | I15: 45767 | J15: 46022 | K15: 0.1 | L15: 20000 | M15: 20000 | T15: 60 | U15: 55890 | V15: Black | W15: 15.11 | X15: 2 | Y15: 14.5 | Z15: Bridal dress | AB15: 15000 | AC15: 45000
A16: 1012 | B16: 1012 | C16: Sherman, Jack | D16: Sherman, Jack | F16: L1 | G16: 100000 | H16: IDR | I16: 45767 | J16: 46022 | K16: 0.1 | L16: 20000 | M16: 20000 | S16: 45000 | T16: 1 | U16: 55890 | V16: Black | W16: 15.11 | X16: 3 | Y16: 15.5 | Z16: Bridal dress | AB16: 15000 | AC16: 45000
A17: 168 | B17: 168 | C17: Soles, Nedra | D17: Soles, Nedra | F17: L1 | G17: 100000 | H17: IDR | I17: 45767 | J17: 46022 | K17: 0.1 | L17: 20000 | M17: 20000 | T17: 1 | U17: 55890 | V17: Black | W17: 15.11 | X17: 4 | Y17: 16.5 | Z17: Bridal dress | AB17: 15000 | AC17: 45000
A18: 2166 | B18: 2166 | C18: Tea, Green | D18: Tea, Green | E18: 1 | F18: L1 | G18: 100000 | H18: USD | I18: 45767 | J18: 46022 | K18: 0.1 | L18: 20000 | M18: 20000 | T18: 10 | U18: 55890 | V18: Black | W18: 15.11 | X18: stylo | Y18: 17.5 | Z18: Bridal dress | AB18: 15000 | AC18: 45000
A19: 1010 | B19: 1010 | C19: Tucker, Darla | D19: Tucker, Darla | E19: 1 | F19: L1 | G19: 100000 | H19: USD | I19: 45767 | J19: 46022 | K19: 0.1 | L19: 20000 | M19: 20000 | S19: 12000 | T19: 81 | U19: 55890 | V19: Black | W19: ok' | X19: stylo | Y19: 19.5 | Z19: Bridal dress | AB19: 15000 | AC19: 45000
A20: 2001 | B20: 2001 | C20: Ward Jr, Lloyd | D20: Ward Jr, Lloyd | E20: 1 | F20: L1 | G20: 100000 | H20: USD | I20: 45767 | J20: 46022 | K20: 0.1 | L20: 20000 | M20: 20000 | T20: 81 | U20: 55890 | V20: Black | W20: test | X20: stylo | Y20: 20.5 | Z20: Bridal dress | AB20: 15000 | AC20: 45000

Sheet Users
A1: Emp Id | B1: User Name First | C1: User Name Last | D1: User Type | E1: User Principal Name | F1: Login Id | G1: Email Address | H1: User Password | I1: User Time Zone
A2: 72 | B2: Beverly | C2: Davis | D2: Employee | E2: bdavis@dartican.com | F2: bdavis | G2: bdavis@dartican.com | H2: open
A3: 162 | B3: Calvin | C3: Thompson | D3: Employee | E3: calvin@dartican.com | F3: calvin | G3: calvin@dartican.com | H3: open
A4: 166 | B4: Joe | C4: Montana | F4: jmontana | G4: jmontana@dartican.com | H4: open
A5: 168 | B5: Nedra | C5: Soles | F5: nsoles | G5: nsoles@dartican.com | H5: open
A6: 1012 | B6: Jack | C6: Sherman | D6: Employee | E6: jsherman@dartican.com | F6: jsherman | G6: jsherman@dartican.com | H6: open
A7: 1113 | B7: Sam | C7: Duncan | D7: Employee | E7: sduncan@dartican.com | F7: sduncan | G7: sduncan@dartican.com | H7: open
A8: 80 | B8: Charmain | C8: Jackson | D8: Employee | E8: cjackson@dartican.com | F8: cjackson | G8: cjackson@dartican.com | H8: open
A9: 2166 | B9: Green | C9: Tea | D9: Employee | E9: tgreen@dartican.com | F9: tgreen | G9: tgreen@dartican.com | H9: open
A10: 1117 | B10: Richele | C10: Ramsey | D10: Employee | E10: rramsey@dartican.com | F10: rramsey | G10: rramsey@dartican.com | H10: open
A11: 1114 | B11: DeDe | C11: Sampson | D11: Employee | E11: dsampson@dartican.com | F11: dsampson | G11: dsampson@dartican.com | H11: open
A12: 2013 | B12: James | C12: Yokay | D12: Employee | E12: jyokay@dartican.com | F12: jyokay | G12: jyokay@dartican.com | H12: open
A13: 1121 | B13: Sarah | C13: Masters | D13: Employee | E13: msarah@dartican.com | F13: msarah | G13: msarah@dartican.com | H13: open
A14: 1010 | B14: Darla | C14: Tucker | D14: Employee | E14: dtucker@dartican.com | F14: dtucker | G14: dtucker@dartican.com | H14: open
A15: 2001 | B15: Lloyd | C15: Ward Jr | D15: Employee | E15: jward@dartican.com | F15: jward | G15: jward@dartican.com | H15: open

Sheet Jobsss
A1: Job Code | B1: Job Title | C1: Current Position Title | D1: Job Family Code | E1: Job Family Name | F1: Job Discipline Name | G1: Job Level | H1: Grade Level | I1: FLSA | J1: Salary Grade | K1: Structure Region | L1: Structure Item | M1: Display Order | N1: Structure Name
A2: J001 | B2: Certified Doc Aide | C2: Certified Doc Aide | D2: ACC | E2: Accounting | F2: Money out | G2: OK | H2: GRD-E06 | I2: Exempt | J2: E06 | L2: E06 | M2: 1 | N2: Exempt US
A3: J002 | B3: Certified Nurse Aide | C3: Certified Nurse Aide | D3: OPS | E3: Operations | F3: Med | G3: OK | H3: GRD-E06 | I3: Exempt | J3: E06 | L3: E06 | M3: 2 | N3: Exempt US
A4: J003 | B4: LVN | C4: LVN | D4: OPS | E4: Operations | F4: Med | G4: OK | H4: GRD-E10 | I4: Exempt | J4: E10 | L4: E10 | M4: 3 | N4: Exempt US
A5: J004 | B5: RN | C5: RN | D5: OPS | E5: Operations | F5: Med | G5: OK | H5: GRD-E12 | I5: Exempt | J5: E12 | L5: E12 | M5: 4 | N5: Exempt US
A6: J005 | B6: A/P Specialist | C6: A/P Specialist | D6: ACC | E6: Accounting | F6: Money out | G6: OK | H6: GRD-E14 | I6: Exempt | J6: E14 | L6: E14 | M6: 5 | N6: Exempt US
A7: J006 | B7: A/R Specialist-Billing | C7: A/R Specialist-Billing | D7: ACC | E7: Accounting | F7: Money In | G7: OK | H7: GRD-E14 | I7: Exempt | J7: E14 | L7: E14 | M7: 6 | N7: Exempt US
A8: J007 | B8: HR Coordinator | C8: HR Coordinator | D8: HR | E8: Human\ Resources | F8: People | G8: OK | H8: GRD-E14 | I8: Exempt | J8: E14 | L8: E14 | M8: 7 | N8: Exempt US
A9: J008 | B9: HR Coordinator/AA | C9: HR Coordinator/AA | D9: HR | E9: Human Resources | F9: People | G9: OK | H9: GRD-E14 | I9: Exempt | J9: E14 | L9: E14 | M9: 8 | N9: Exempt US
A10: J009 | B10: P/R Specialist | C10: P/R Specialist | D10: OPS | E10: Operations | F10: Work | G10: OK | H10: GRD-E14 | I10: Exempt | J10: E14 | L10: E14 | M10: 9 | N10: Exempt US
A11: J010 | B11: Administrative Assistant I | C11: Administrative Assistant I | D11: Admin | E11: Administration | F11: not real work | G11: OK | H11: GRD-E16 | I11: Exempt | J11: E16 | L11: E16 | M11: 10 | N11: Exempt US
A12: J011 | B12: Administrative Assistant III | C12: Administrative Assistant III | D12: Admin | E12: Administration | F12: not real work | G12: OK | H12: GRD-E18 | I12: Exempt | J12: E18 | L12: E18 | M12: 11 | N12: Exempt US
A13: J012 | B13: Director of Nursing | C13: Director of Nursing | D13: OPS | E13: Operations | F13: Work | G13: OK | H13: GRD-E18 | I13: Exempt | J13: E18 | L13: E18 | M13: 12 | N13: Exempt US
... A21: J020 | B21: Human Resource Manager | C21: Human Resource Manager | D21: HR | E21: Human Resources | F21: People | G21: OK | H21: GRD-E28 | I21: Exempt | J21: E28 | L21: E28 | M21: 20 | N21: Exempt CAD
A22: J021 | B22: Sales/Marketing Manager | C22: Sales/Marketing Manager | F22: Money In | G22: OK | H22: GRD-E29 | I22: Exempt | J22: E29 | L22: E29 | M22: 21 | N22: Exempt CAD
A23: J022 | B23: IT Manager | C23: IT Manager | D23: IT | E23: Technology | F23: Tech | G23: OK | H23: GRD-E32 | I23: Exempt | J23: E20 | K23: Australian | L23: E20 | M23: 22
A24: J023 | B24: Controller | C24: Controller | D24: ACC | E24: Accounting | F24: Money tracker | G24: Up There | H24: GRD-E34 | I24: Exempt | J24: E20 | K24: Australian | L24: E20 | M24: 23
A25: J024 | B25: Director of HR | C25: Director of HR | D25: HR | E25: Human Resources | F25: People | G25: Up There | H25: GRD-E34 | I25: Exempt | J25: E21 | K25: Australian | L25: E21 | M25: 24
A26: J025 | B26: Director of Operations | C26: Director of Operations | D26: OPS | E26: Operations | F26: Work | G26: Up There | H26: GRD-E34 | I26: Exempt | J26: E34 | L26: E34 | M26: 25 | N26: Exempt CAD
A27: J026 | B27: Director of Operations | C27: Director of Operations | D27: ACC | E27: Accounting | F27: Money tracker | G27: Up There | H27: GRD-E38 | I27: Exempt | J27: E38 | L27: E38 | M27: 26 | N27: Exempt CAD
A28: J027 | B28: Director of Operations | C28: Director of Operations | D28: IT | E28: Technology | F28: Tech | G28: Up There | H28: GRD-E38 | I28: Exempt | J28: E38 | L28: E38 | M28: 27 | N28: Exempt CAD
A29: J028 | B29: Director of Operations | C29: Director of Operations | D29: OPS | E29: Operations | F29: Work | G29: Near Top | H29: GRD-E38 | I29: Exempt | J29: E38 | L29: E38 | M29: 28 | N29: Exempt CAD
A30: J029 | B30: Director of Operations | C30: Director of Operations | F30: not real work | G30: Top | H30: GRD-E40 | I30: Exempt | J30: E40 | L30: E40 | M30: 29 | N30: Exempt CAD

Sheet Jobs
A1: Job Code | B1: Job Title | C1: Current Position Title | D1: Job Family Code | E1: Job Family Name | F1: Job Discipline Name | G1: Job Level | H1: Grade Level | I1: FLSA | J1: Salary Grade | K1: Structure Region | L1: Structure Item | M1: Display Order | N1: Structure Name
A2: J001 | B2: Certified Doc Aide | C2: Certified Doc Aide! | D2: ACC | E2: Accounting! | F2: Money out | G2: OK | H2: GRD-E06 | I2: Exempt | J2: E06 | L2: E06 | M2: 1 | N2: Exempt US
A3: J002 | B3: Certified Nurse Aide | C3: Certified Nurse Aide@ | D3: OPS | E3: Operations@ | F3: Med | G3: OK | H3: GRD-E06 | I3: Exempt | J3: E06 | L3: E06 | M3: 2 | N3: Exempt US
A4: J003 | B4: LVN | C4: LVN# | D4: OPS | E4: Operations# | F4: Med | G4: OK | H4: GRD-E10 | I4: Exempt | J4: E10 | L4: E10 | M4: 3 | N4: Exempt US
A5: J004 | B5: RN | C5: RN$ | D5: OPS | E5: Operations$ | F5: Med | G5: OK | H5: GRD-E12 | I5: Exempt | J5: E12 | L5: E12 | M5: 4 | N5: Exempt US
A6: J005 | B6: A/P Specialist | C6: A/P Specialist% | D6: ACC | E6: Accounting% | F6: Money out | G6: OK | H6: GRD-E14 | I6: Exempt | J6: E14 | L6: E14 | M6: 5 | N6: Exempt US
A7: J006 | B7: A/R Specialist-Billing | C7: A/R Specialist-Billing^ | D7: ACC | E7: Accounting^ | F7: Money In | G7: OK | H7: GRD-E14 | I7: Exempt | J7: E14 | L7: E14 | M7: 6 | N7: Exempt US
A8: J007 | B8: HR Coordinator& | C8: HR Coordinator& | D8: HR | E8: Human\ Resources& | F8: People | G8: OK | H8: GRD-E14 | I8: Exempt | J8: E14 | L8: E14 | M8: 7 | N8: Exempt US
A9: J008 | B9: HR Coordinator/AA | C9: HR Coordinator/AA* | D9: HR | E9: Human Resources* | F9: People | G9: OK | H9: GRD-E14 | I9: Exempt | J9: E14 | L9: E14 | M9: 8 | N9: Exempt US
A10: J009 | B10: P/R Specialist | C10: P/R Specialist( | D10: OPS | E10: Operations( | F10: Work | G10: OK | H10: GRD-E14 | I10: Exempt | J10: E14 | L10: E14 | M10: 9 | N10: Exempt US
A11: J010 | B11: Administrative Assistant I | C11: Administrative Assistant I ) | D11: Admin | E11: Administration) | F11: not real work | G11: OK | H11: GRD-E16 | I11: Exempt | J11: E16 | L11: E16 | M11: 10 | N11: Exempt US
A12: J011 | B12: Administrative Assistant III _ | C12: Administrative Assistant III _ | D12: Admin | E12: Administration_ | F12: not real work | G12: OK | H12: GRD-E18 | I12: Exempt | J12: E18 | L12: E18 | M12: 11 | N12: Exempt US
A13: J012 | B13: Director of Nursing - | C13: Director of Nursing - | D13: OPS | E13: Operations- | F13: Work | G13: OK | H13: GRD-E18 | I13: Exempt | J13: E18 | L13: E18 | M13: 12 | N13: Exempt US
... A21: J020 | B21: Human Resource Manager | C21: Human Resource Manager \ | D21: HR | E21: Human Resources\ | F21: People | G21: OK | H21: GRD-E28 | I21: Exempt | J21: E28 | L21: E28 | M21: 20 | N21: Exempt CAD
A22: J021 | B22: Sales/Marketing Manager | C22: Sales/Marketing Manager : | E22: Marketing : | F22: Money In | G22: OK | H22: GRD-E29 | I22: Exempt | J22: E29 | L22: E29 | M22: 21 | N22: Exempt CAD
A23: J022 | B23: IT Manager | C23: IT Manager ; | D23: IT | E23: Technology ; | F23: Tech | G23: OK | H23: GRD-E32 | I23: Exempt | J23: E20 | K23: Australian | L23: E20 | M23: 22
